Workbook

Sheet Calendar
A1: Day | B1: Date | C1: Weekday | D1: Slot | E1: Post time (IST) | F1: Episode | G1: Phase | H1: Series | I1: Mode | J1: Code | K1: Tool(s) | L1: Pillar | M1: Draft hook (rewrite after test) | N1: The test | O1: Free path | P1: Affiliate status | Q1: On-screen label | R1: YouTube title (draft) | S1: Hashtags | T1: Status
A2: 1 | B2: =Settings!$B$3+A2-1 -> 46314 | C2: =TEXT(B2,"ddd") -> Mon | D2: A | E2: =Settings!$B$4 -> 06:30 | F2: E001 | G2: 1 Collect | H2: Field Specimen | I2: Live specimen | J2: 001 | K2: Tripo | L2: 3D | M2: This mug was a phone photo 40 seconds ago. | N2: One phone photo of a real mug to a textured 3D model, one try | O2: Free: 200 credits/mo, models public + non-commercial | P2: Confirmed program | Q2: Affiliate | R2: Tripo: This mug was a phone photo 40 seconds ago | Specimen Nº001 | S2: #3dmodeling #ai3d #3dprinting #specimindlab | T2: Planned
A3: 1 | B3: =Settings!$B$3+A3-1 -> 46314 | C3: =TEXT(B3,"ddd") -> Mon | D3: B | E3: =Settings!$B$5 -> 18:30 | F3: E002 | G3: 1 Collect | H3: Free Range | I3: Live specimen | J3: 002 | K3: Hunyuan3D | L3: 3D | M3: Tencent's free 3D generator vs my desk lamp. | N3: Photo of a desk lamp to mesh; inspect the thin arm | O3: Free: ~20 generations/day, open weights | P3: No program known (Unpaid) | Q3: Unpaid | R3: Hunyuan3D: Tencent's free 3D generator vs my desk lamp | Specimen Nº002 | S3: #3dmodeling #ai3d #3dprinting #specimindlab | T3: Planned
A4: 2 | B4: =Settings!$B$3+A4-1 -> 46315 | C4: =TEXT(B4,"ddd") -> Tue | D4: A | E4: =Settings!$B$4 -> 06:30 | F4: E003 | G4: 1 Collect | H4: Rare Sighting | I4: Live specimen | J4: 003 | K4: TRELLIS 2 | L4: 3D | M4: Microsoft's open-source 3D model, free in a browser tab. | N4: Concept art of a creature to 3D via the free demo | O4: Open-source; free Hugging Face Space demo | P4: No program known (Unpaid) | Q4: Unpaid | R4: TRELLIS 2: Microsoft's open-source 3D model, free in a browser tab | Specimen Nº003 | S4: #3dmodeling #ai3d #3dprinting #specimindlab | T4: Planned
A5: 2 | B5: =Settings!$B$3+A5-1 -> 46315 | C5: =TEXT(B5,"ddd") -> Tue | D5: B | E5: =Settings!$B$5 -> 18:30 | F5: E004 | G5: 1 Collect | H5: Field Specimen | I5: Live specimen | J5: 004 | K5: Kling 3.0 | L5: Video | M5: Free AI video, refilled every day. Here's day one. | N5: Image-to-video of a still-life photo, 5 s, one try | O5: Free: 66 credits/day, 720p, 5 s | P5: Check for program | Q5: Affiliate if approved, else Unpaid | R5: Kling 3.0: Free AI video, refilled every day. Here's day one | Specimen Nº004 | S5: #aivideo #videogeneration #filmmaking #specimindlab | T5: Planned
A6: 3 | B6: =Settings!$B$3+A6-1 -> 46316 | C6: =TEXT(B6,"ddd") -> Wed | D6: A | E6: =Settings!$B$4 -> 06:30 | F6: E005 | G6: 1 Collect | H6: Plate | I6: Live specimen | J6: P01 | K6: Tripo vs Meshy vs Hunyuan3D | L6: 3D | M6: Same photo, three 3D specimens. | N6: One phone photo of a ceramic owl through all three free tiers | O6: All three on free tiers | P6: Check for program, Confirmed program, No program known (Unpaid) | Q6: Affiliate on any approved specimen | R6: Tripo vs Meshy vs Hunyuan3D: same photo, three 3d specimens | Plate P01 | S6: #3dmodeling #ai3d #3dprinting #aicomparison #specimindlab | T6: Planned
A7: 3 | B7: =Settings!$B$3+A7-1 -> 46316 | C7: =TEXT(B7,"ddd") -> Wed | D7: B | E7: =Settings!$B$5 -> 18:30 | F7: E006 | G7: 1 Collect | H7: Field Sketch | I7: Field sketch | J7: 006 | K7: Midjourney | L7: Image | M7: Still the taste leader? A desk study. | N7: Desk study: public gallery, pricing, who it's for | O7: No free tier (Field sketch) | P7: Check for program | Q7: Affiliate if approved, else Unpaid | R7: Midjourney: Still the taste leader? A desk study | Specimen Nº006 | S7: #aiart #aiimage #design #specimindlab | T7: Planned
A8: 4 | B8: =Settings!$B$3+A8-1 -> 46317 | C8: =TEXT(B8,"ddd") -> Thu | D8: A | E8: =Settings!$B$4 -> 06:30 | F8: E007 | G8: 1 Collect | H8: Field Specimen | I8: Live specimen | J8: 007 | K8: ElevenLabs | L8: Audio | M8: Sound effects from a sentence, not a library. | N8: Generate 'drawer sliding shut in a museum' SFX | O8: Free: monthly characters, attribution required | P8: Confirmed program | Q8: Affiliate | R8: ElevenLabs: Sound effects from a sentence, not a library | Specimen Nº007 | S8: #aimusic #audio #soundeffects #specimindlab | T8: Planned
A9: 4 | B9: =Settings!$B$3+A9-1 -> 46317 | C9: =TEXT(B9,"ddd") -> Thu | D9: B | E9: =Settings!$B$5 -> 18:30 | F9: E008 | G9: 1 Collect | H9: Mimicry | I9: Live specimen | J9: M01 | K9: Photoroom | L9: Image | M9: A product photo: real or Photoroom? | N9: Make the AI side on the free tier; shoot the real side ourselves; comment A or B | O9: Free tier | P9: Check for program | Q9: Unpaid (the reveal names the tool) | R9: A product photo: real or Photoroom? | Mimicry M01 | S9: #aiart #aiimage #design #aiorreal #specimindlab | T9: Planned
A10: 5 | B10: =Settings!$B$3+A10-1 -> 46318 | C10: =TEXT(B10,"ddd") -> Fri | D10: A | E10: =Settings!$B$4 -> 06:30 | F10: E009 | G10: 1 Collect | H10: Dissection | I10: Live specimen | J10: D01 | K10: Tripo | L10: 3D | M10: Phone photo to an animated 3D character. | N10: Photo to mesh, auto-rig, walk cycle, all free tier | O10: Free tiers only | P10: Mixed | Q10: Affiliate on any approved specimen | R10: Phone photo to an animated 3D character with free AI tools | Dissection D01 | S10: #3dmodeling #ai3d #3dprinting #workflow #specimindlab | T10: Planned
A11: 5 | B11: =Settings!$B$3+A11-1 -> 46318 | C11: =TEXT(B11,"ddd") -> Fri | D11: B | E11: =Settings!$B$5 -> 18:30 | F11: E010 | G11: 1 Collect | H11: Rare Sighting | I11: Live specimen | J11: 009 | K11: Hitem3D | L11: 3D | M11: A 3D tool built for people who own a 3D printer. | N11: Figurine photo to watertight, print-ready mesh | O11: Free tier (verify) | P11: Check for program | Q11: Affiliate if approved, else Unpaid | R11: Hitem3D: A 3D tool built for people who own a 3D printer | Specimen Nº009 | S11: #3dmodeling #ai3d #3dprinting #specimindlab | T11: Planned
A12: 6 | B12: =Settings!$B$3+A12-1 -> 46319 | C12: =TEXT(B12,"ddd") -> Sat | D12: A | E12: =Settings!$B$4 -> 06:30 | F12: E011 | G12: 1 Collect | H12: Field Specimen | I12: Live specimen | J12: 010 | K12: Gamma | L12: Work | M12: A whole slide deck from one sentence. | N12: 10-slide deck on composting; count fixes needed | O12: Free credits | P12: Check for program | Q12: Affiliate if approved, else Unpaid | R12: Gamma: A whole slide deck from one sentence | Specimen Nº010 | S12: #productivity #studytips #worktools #specimindlab | T12: Planned
A13: 6 | B13: =Settings!$B$3+A13-1 -> 46319 | C13: =TEXT(B13,"ddd") -> Sat | D13: B | E13: =Settings!$B$5 -> 18:30 | F13: E012 | G13: 1 Collect | H13: Free Range | I13: Live specimen | J13: 011 | K13: Gemini image | L13: Image | M13: Edit a photo by typing what to change. | N13: Remove a person from a beach photo, then relight it | O13: Free in Gemini app | P13: No program known (Unpaid) | Q13: Unpaid | R13: Gemini image: Edit a photo by typing what to change | Specimen Nº011 | S13: #aiart #aiimage #design #specimindlab | T13: Planned
A14: 7 | B14: =Settings!$B$3+A14-1 -> 46320 | C14: =TEXT(B14,"ddd") -> Sun | D14: A | E14: =Settings!$B$4 -> 06:30 | F14: E013 | G14: 1 Collect | H14: The Drawer | I14: Built from the week's renders | J14: W01 | K14: This week's specimens | L14: All | M14: Week 1: every specimen we pinned. | N14: Recap each label + verdict in 30 s; end on next week's teaser | O14: No tool use | P14: n/a | Q14: Unpaid | R14: Every AI tool we tested this week | The Drawer W01 | S14: #aitools #weeklyrecap #specimindlab | T14: Planned
A15: 7 | B15: =Settings!$B$3+A15-1 -> 46320 | C15: =TEXT(B15,"ddd") -> Sun | D15: B | E15: =Settings!$B$5 -> 18:30 | F15: E014 | G15: 1 Collect | H15: Extinction Watch | I15: Field sketch | J15: X01 | K15: See test | L15: Any | M15: Sora is gone. What replaced it? | N15: OpenAI closed the Sora app in Apr 2026 and the API on 24 Sep 2026; compare 3 free successors | O15: Desk study | P15: n/a | Q15: Unpaid | R15: Sora is gone. What replaced it? | Extinction Watch X01 | S15: #ainews #aitools #specimindlab | T15: Planned
A16: 8 | B16: =Settings!$B$3+A16-1 -> 46321 | C16: =TEXT(B16,"ddd") -> Mon | D16: A | E16: =Settings!$B$4 -> 06:30 | F16: E015 | G16: 1 Collect | H16: Field Specimen | I16: Live specimen | J16: 008 | K16: Photoroom | L16: Image | M16: Bedroom product photo to studio shot. | N16: Messy-table product photo to clean studio background | O16: Free tier | P16: Check for program | Q16: Affiliate if approved, else Unpaid | R16: Photoroom: Bedroom product photo to studio shot | Specimen Nº008 | S16: #aiart #aiimage #design #specimindlab | T16: Planned
A17: 8 | B17: =Settings!$B$3+A17-1 -> 46321 | C17: =TEXT(B17,"ddd") -> Mon | D17: B | E17: =Settings!$B$5 -> 18:30 | F17: E016 | G17: 1 Collect | H17: Free Range | I17: Live specimen | J17: 012 | K17: NotebookLM | L17: Work | M17: Upload a textbook, get a two-host podcast. | N17: Chapter PDF to audio overview; check accuracy | O17: Free | P17: No program known (Unpaid) | Q17: Unpaid | R17: NotebookLM: Upload a textbook, get a two-host podcast | Specimen Nº012 | S17: #productivity #studytips #worktools #specimindlab | T17: Planned
A18: 9 | B18: =Settings!$B$3+A18-1 -> 46322 | C18: =TEXT(B18,"ddd") -> Tue | D18: A | E18: =Settings!$B$4 -> 06:30 | F18: E017 | G18: 1 Collect | H18: Rare Sighting | I18: Live specimen | J18: 013 | K18: Happy Shrimp | L18: Audio | M18: Alibaba's new song generator, spotted early. | N18: Same lo-fi prompt as Suno, compare structure | O18: Free (verify) | P18: No program known (Unpaid) | Q18: Unpaid | R18: Happy Shrimp: Alibaba's new song generator, spotted early | Specimen Nº013 | S18: #aimusic #audio #soundeffects #specimindlab | T18: Planned
A19: 9 | B19: =Settings!$B$3+A19-1 -> 46322 | C19: =TEXT(B19,"ddd") -> Tue | D19: B | E19: =Settings!$B$5 -> 18:30 | F19: E018 | G19: 1 Collect | H19: Field Specimen | I19: Live specimen | J19: 014 | K19: Lovable | L19: Build | M19: An app from one paragraph. Does it run? | N19: Habit tracker from one paragraph; test 3 features | O19: Free daily credits | P19: Check for program | Q19: Affiliate if approved, else Unpaid | R19: Lovable: An app from one paragraph. Does it run | Specimen Nº014 | S19: #nocode #vibecoding #appdev #specimindlab | T19: Planned
A20: 10 | B20: =Settings!$B$3+A20-1 -> 46323 | C20: =TEXT(B20,"ddd") -> Wed | D20: A | E20: =Settings!$B$4 -> 06:30 | F20: E019 | G20: 1 Collect | H20: Plate | I20: Live specimen | J20: P02 | K20: Kling 3.0 vs Hailuo (MiniMax) vs Seedance (Dreamina) | L20: Video | M20: Same prompt, three free video models. | N20: 'Steam rising from a cup by a rainy window', 5 s each | O20: All three on free tiers | P20: Check for program | Q20: Affiliate on any approved specimen | R20: Kling 3.0 vs Hailuo (MiniMax) vs Seedance (Dreamina): same prompt, three free video models | Plate P02 | S20: #aivideo #videogeneration #filmmaking #aicomparison #specimindlab | T20: Planned
A21: 10 | B21: =Settings!$B$3+A21-1 -> 46323 | C21: =TEXT(B21,"ddd") -> Wed | D21: B | E21: =Settings!$B$5 -> 18:30 | F21: E020 | G21: 1 Collect | H21: Field Sketch | I21: Field sketch | J21: 017 | K21: Veo 3.1 (Flow) | L21: Video | M21: The most realistic video model, on paper. | N21: Desk study: public examples, prices, access | O21: Paid Google AI plan (Field sketch) | P21: No program known (Unpaid) | Q21: Unpaid | R21: Veo 3.1 (Flow): The most realistic video model, on paper | Specimen Nº017 | S21: #aivideo #videogeneration #filmmaking #specimindlab | T21: Planned
A22: 11 | B22: =Settings!$B$3+A22-1 -> 46324 | C22: =TEXT(B22,"ddd") -> Thu | D22: A | E22: =Settings!$B$4 -> 06:30 | F22: E021 | G22: 1 Collect | H22: Field Specimen | I22: Live specimen | J22: 005 | K22: Meshy | L22: 3D | M22: Can a free 3D tool make a game-ready sword? | N22: Text prompt to a low-poly sword; check polygon count | O22: Free: 100 credits/mo, CC BY 4.0 (credit Meshy) | P22: Check for program | Q22: Affiliate if approved, else Unpaid | R22: Meshy: Can a free 3D tool make a game-ready sword | Specimen Nº005 | S22: #3dmodeling #ai3d #3dprinting #specimindlab | T22: Planned
A23: 11 | B23: =Settings!$B$3+A23-1 -> 46324 | C23: =TEXT(B23,"ddd") -> Thu | D23: B | E23: =Settings!$B$5 -> 18:30 | F23: E022 | G23: 1 Collect | H23: Mimicry | I23: Live specimen | J23: M02 | K23: Tripo | L23: 3D | M23: A mug: phone photo or Tripo render? | N23: Make the AI side on the free tier; shoot the real side ourselves; comment A or B | O23: Free: 200 credits/mo, models public + non-commercial | P23: Confirmed program | Q23: Unpaid (the reveal names the tool) | R23: A mug: phone photo or Tripo render? | Mimicry M02 | S23: #3dmodeling #ai3d #3dprinting #aiorreal #specimindlab | T23: Planned
A24: 12 | B24: =Settings!$B$3+A24-1 -> 46325 | C24: =TEXT(B24,"ddd") -> Fri | D24: A | E24: =Settings!$B$4 -> 06:30 | F24: E023 | G24: 1 Collect | H24: Dissection | I24: Live specimen | J24: D02 | K24: Tripo + Hitem3D | L24: 3D | M24: Sketch to a 3D-printable toy. | N24: Pencil sketch to mesh, sliced in free Bambu Studio | O24: Free tiers only | P24: Mixed | Q24: Affiliate on any approved specimen | R24: Sketch to a 3D-printable toy with free AI tools | Dissection D02 | S24: #3dmodeling #ai3d #3dprinting #workflow #specimindlab | T24: Planned
A25: 12 | B25: =Settings!$B$3+A25-1 -> 46325 | C25: =TEXT(B25,"ddd") -> Fri | D25: B | E25: =Settings!$B$5 -> 18:30 | F25: E024 | G25: 1 Collect | H25: Rare Sighting | I25: Live specimen | J25: 018 | K25: Hookest | L25: Creator | M25: A swipe file of viral video hooks. | N25: Find 5 hooks for an AI-tool video; rate them | O25: Free tier (verify) | P25: Check for program | Q25: Affiliate if approved, else Unpaid | R25: Hookest: A swipe file of viral video hooks | Specimen Nº018 | S25: #contentcreator #videoediting #shortsediting #specimindlab | T25: Planned
A26: 13 | B26: =Settings!$B$3+A26-1 -> 46326 | C26: =TEXT(B26,"ddd") -> Sat | D26: A | E26: =Settings!$B$4 -> 06:30 | F26: E025 | G26: 1 Collect | H26: Field Specimen | I26: Live specimen | J26: 019 | K26: Ideogram | L26: Image | M26: The image model that's best at words. | N26: Poster with 3 lines of exact text | O26: Free daily credits | P26: Check for program | Q26: Affiliate if approved, else Unpaid | R26: Ideogram: The image model that's best at words | Specimen Nº019 | S26: #aiart #aiimage #design #specimindlab | T26: Planned
A27: 13 | B27: =Settings!$B$3+A27-1 -> 46326 | C27: =TEXT(B27,"ddd") -> Sat | D27: B | E27: =Settings!$B$5 -> 18:30 | F27: E026 | G27: 1 Collect | H27: Free Range | I27: Live specimen | J27: 020 | K27: Adobe Podcast Enhance | L27: Audio | M27: Make a phone recording sound like a studio. | N27: Bathroom-echo recording, enhance, A/B | O27: Free tier | P27: No program known (Unpaid) | Q27: Unpaid | R27: Adobe Podcast Enhance: Make a phone recording sound like a studio | Specimen Nº020 | S27: #aimusic #audio #soundeffects #specimindlab | T27: Planned
A28: 14 | B28: =Settings!$B$3+A28-1 -> 46327 | C28: =TEXT(B28,"ddd") -> Sun | D28: A | E28: =Settings!$B$4 -> 06:30 | F28: E027 | G28: 1 Collect | H28: The Drawer | I28: Built from the week's renders | J28: W02 | K28: This week's specimens | L28: All | M28: Week 2: every specimen we pinned. | N28: Recap each label + verdict in 30 s; end on next week's teaser | O28: No tool use | P28: n/a | Q28: Unpaid | R28: Every AI tool we tested this week | The Drawer W02 | S28: #aitools #weeklyrecap #specimindlab | T28: Planned
A29: 14 | B29: =Settings!$B$3+A29-1 -> 46327 | C29: =TEXT(B29,"ddd") -> Sun | D29: B | E29: =Settings!$B$5 -> 18:30 | F29: E028 | G29: 1 Collect | H29: Rare Sighting | I29: Live specimen | J29: 021 | K29: Chit | L29: Work | M29: A printed receipt of your day in Claude Code. | N29: Run for one coding day; show the receipt | O29: Free (verify) | P29: No program known (Unpaid) | Q29: Unpaid | R29: Chit: A printed receipt of your day in Claude Code | Specimen Nº021 | S29: #productivity #studytips #worktools #specimindlab | T29: Planned
A30: 15 | B30: =Settings!$B$3+A30-1 -> 46328 | C30: =TEXT(B30,"ddd") -> Mon | D30: A | E30: =Settings!$B$4 -> 06:30 | F30: E029 | G30: 1 Collect | H30: Field Specimen | I30: Live specimen | J30: 022 | K30: HeyGen | L30: Avatar | M30: Your photo, speaking six languages. | N30: Photo avatar reads one line in 3 languages | O30: Free plan, short videos | P30: Confirmed program | Q30: Affiliate | R30: HeyGen: Your photo, speaking six languages | Specimen Nº022 | S30: #aiavatar #videomarketing #captions #specimindlab | T30: Planned
A31: 15 | B31: =Settings!$B$3+A31-1 -> 46328 | C31: =TEXT(B31,"ddd") -> Mon | D31: B | E31: =Settings!$B$5 -> 18:30 | F31: E030 | G31: 1 Collect | H31: Free Range | I31: Live specimen | J31: 023 | K31: Goblin Tools | L31: Work | M31: The free tool that breaks scary tasks into steps. | N31: 'Clean the garage' into steps, spiciness slider | O31: Free | P31: No program known (Unpaid) | Q31: Unpaid | R31: Goblin Tools: The free tool that breaks scary tasks into steps | Specimen Nº023 | S31: #productivity #studytips #worktools #specimindlab | T31: Planned
A32: 16 | B32: =Settings!$B$3+A32-1 -> 46329 | C32: =TEXT(B32,"ddd") -> Tue | D32: A | E32: =Settings!$B$4 -> 06:30 | F32: E031 | G32: 1 Collect | H32: Rare Sighting | I32: Live specimen | J32: 024 | K32: Lovart | L32: Image | M32: A design agent that makes a whole brand kit. | N32: Brief: coffee cart brand; count usable assets | O32: Free credits (verify) | P32: Check for program | Q32: Affiliate if approved, else Unpaid | R32: Lovart: A design agent that makes a whole brand kit | Specimen Nº024 | S32: #aiart #aiimage #design #specimindlab | T32: Planned
A33: 16 | B33: =Settings!$B$3+A33-1 -> 46329 | C33: =TEXT(B33,"ddd") -> Tue | D33: B | E33: =Settings!$B$5 -> 18:30 | F33: E032 | G33: 1 Collect | H33: Field Specimen | I33: Live specimen | J33: 025 | K33: Descript | L33: Creator | M33: Edit video by deleting words in a transcript. | N33: Remove all 'um's from a 2-minute recording | O33: Free plan | P33: Confirmed program | Q33: Affiliate | R33: Descript: Edit video by deleting words in a transcript | Specimen Nº025 | S33: #contentcreator #videoediting #shortsediting #specimindlab | T33: Planned
A34: 17 | B34: =Settings!$B$3+A34-1 -> 46330 | C34: =TEXT(B34,"ddd") -> Wed | D34: A | E34: =Settings!$B$4 -> 06:30 | F34: E033 | G34: 1 Collect | H34: Plate | I34: Live specimen | J34: P03 | K34: Ideogram vs Recraft vs Gemini image | L34: Image | M34: Same logo brief, three image models. | N34: Logo for 'Lantern Bakery' with exact spelling | O34: All three on free tiers | P34: Check for program, No program known (Unpaid) | Q34: Affiliate on any approved specimen | R34: Ideogram vs Recraft vs Gemini image: same logo brief, three image models | Plate P03 | S34: #aiart #aiimage #design #aicomparison #specimindlab | T34: Planned
A35: 17 | B35: =Settings!$B$3+A35-1 -> 46330 | C35: =TEXT(B35,"ddd") -> Wed | D35: B | E35: =Settings!$B$5 -> 18:30 | F35: E034 | G35: 1 Collect | H35: Field Sketch | I35: Field sketch | J35: 027 | K35: Synthesia | L35: Avatar | M35: Corporate training videos without a camera. | N35: Desk study: plans, use cases, limits | O35: Free plan limited (Field sketch) | P35: Confirmed program | Q35: Affiliate | R35: Synthesia: Corporate training videos without a camera | Specimen Nº027 | S35: #aiavatar #videomarketing #captions #specimindlab | T35: Planned
A36: 18 | B36: =Settings!$B$3+A36-1 -> 46331 | C36: =TEXT(B36,"ddd") -> Thu | D36: A | E36: =Settings!$B$4 -> 06:30 | F36: E035 | G36: 1 Collect | H36: Field Specimen | I36: Live specimen | J36: 016 | K36: Seedance (Dreamina) | L36: Video | M36: The free video model with no watermark. | N36: Product shot of a shoe turning on a plinth | O36: Free daily credits, 1080p no watermark (verify) | P36: Check for program | Q36: Affiliate if approved, else Unpaid | R36: Seedance (Dreamina): The free video model with no watermark | Specimen Nº016 | S36: #aivideo #videogeneration #filmmaking #specimindlab | T36: Planned
A37: 18 | B37: =Settings!$B$3+A37-1 -> 46331 | C37: =TEXT(B37,"ddd") -> Thu | D37: B | E37: =Settings!$B$5 -> 18:30 | F37: E036 | G37: 1 Collect | H37: Mimicry | I37: Live specimen | J37: M03 | K37: Kling 3.0 | L37: Video | M37: Rain on glass: filmed or Kling? | N37: Make the AI side on the free tier; shoot the real side ourselves; comment A or B | O37: Free: 66 credits/day, 720p, 5 s | P37: Check for program | Q37: Unpaid (the reveal names the tool) | R37: Rain on glass: filmed or Kling? | Mimicry M03 | S37: #aivideo #videogeneration #filmmaking #aiorreal #specimindlab | T37: Planned
A38: 19 | B38: =Settings!$B$3+A38-1 -> 46332 | C38: =TEXT(B38,"ddd") -> Fri | D38: A | E38: =Settings!$B$4 -> 06:30 | F38: E037 | G38: 1 Collect | H38: Dissection | I38: Live specimen | J38: D03 | K38: Ideogram + Photoroom + Lovable | L38: Image | M38: One idea to a launch page. | N38: Logo, product shot, landing page in under an hour | O38: Free tiers only | P38: Mixed | Q38: Affiliate on any approved specimen | R38: One idea to a launch page with free AI tools | Dissection D03 | S38: #aiart #aiimage #design #workflow #specimindlab | T38: Planned
A39: 19 | B39: =Settings!$B$3+A39-1 -> 46332 | C39: =TEXT(B39,"ddd") -> Fri | D39: B | E39: =Settings!$B$5 -> 18:30 | F39: E038 | G39: 1 Collect | H39: Rare Sighting | I39: Live specimen | J39: 028 | K39: Vizcom | L39: Image | M39: Industrial designers' sketch-to-render tool. | N39: Napkin sketch of a kettle to product render | O39: Free plan (verify) | P39: Check for program | Q39: Affiliate if approved, else Unpaid | R39: Vizcom: Industrial designers' sketch-to-render tool | Specimen Nº028 | S39: #aiart #aiimage #design #specimindlab | T39: Planned
A40: 20 | B40: =Settings!$B$3+A40-1 -> 46333 | C40: =TEXT(B40,"ddd") -> Sat | D40: A | E40: =Settings!$B$4 -> 06:30 | F40: E039 | G40: 1 Collect | H40: Field Specimen | I40: Live specimen | J40: 026 | K40: Recraft | L40: Image | M40: AI that outputs real vector files, not pixels. | N40: Icon set of 6 kitchen tools as SVG | O40: Free tier | P40: Check for program | Q40: Affiliate if approved, else Unpaid | R40: Recraft: AI that outputs real vector files, not pixels | Specimen Nº026 | S40: #aiart #aiimage #design #specimindlab | T40: Planned
...

Sheet Settings
A1: SPECIMIND - 90-day calendar settings
A3: Start date (Day 1, a Monday) | B3: 46314 | C3: Edit this cell. Every date in the Calendar recalculates. The weekly series pattern assumes Day 1 is a Monday.
A4: Slot A post time (IST) | B4: 06:30 | C4: Equals 9:00 pm ET the previous evening (US prime time)
A5: Slot B post time (IST) | B5: 18:30 | C5: Equals 9:00 am ET (US morning), 1:00 pm UK
A6: Last day (formula) | B6: =B3+89 -> 46403
A8: Legend
A9: Yellow cell, blue text | C9: An input you can change
A10: Code column | C10: What viewers comment / type: 001 = catalog number, P = Plate, D = Dissection, M = Mimicry, W = Drawer, X = Extinction
A11: Draft hook | C11: A starting line only. Rewrite it after the real test so it states what actually happened.
A12: Affiliate status | C12: 'Confirmed program' = a public program found in research (apply; approval not guaranteed). 'Check' = look for one before the episode. Free-tier notes marked 'verify' must be re-checked the week of filming.
A13: Label | C13: Shown on the pinned label for the whole video. Use 'Affiliate' only once you are approved and the link in the hub is yours.
A14: Status | C14: Planned > Researched > Captured > Rendered > Posted

Sheet Catalog
A1: Nº | B1: Tool | C1: Pillar | D1: First episode | E1: First date | F1: Free path (re-verify before filming) | G1: Affiliate status | H1: Source / note
A2: 001 | B2: Tripo | C2: 3D | D2: =Calendar!F2 -> E001 | E2: =Calendar!B2 -> 46314 | F2: Free: 200 credits/mo, models public + non-commercial | G2: Confirmed program | H2: https://www.tripo3d.ai/affiliate
A3: 002 | B3: Hunyuan3D | C3: 3D | D3: =Calendar!F3 -> E002 | E3: =Calendar!B3 -> 46314 | F3: Free: ~20 generations/day, open weights | G3: No program known (Unpaid) | H3: Free-tier note from 2026 comparison articles; verify
A4: 003 | B4: TRELLIS 2 | C4: 3D | D4: =Calendar!F4 -> E003 | E4: =Calendar!B4 -> 46315 | F4: Open-source; free Hugging Face Space demo | G4: No program known (Unpaid) | H4: Free-tier note from 2026 comparison articles; verify
A5: 004 | B5: Kling 3.0 | C5: Video | D5: =Calendar!F5 -> E004 | E5: =Calendar!B5 -> 46315 | F5: Free: 66 credits/day, 720p, 5 s | G5: Check for program | H5: Free-tier note from 2026 comparison articles; verify
A6: 005 | B6: Meshy | C6: 3D | D6: =Calendar!F6 -> E005 | E6: =Calendar!B6 -> 46316 | F6: Free: 100 credits/mo, CC BY 4.0 (credit Meshy) | G6: Check for program | H6: Free-tier note from 2026 comparison articles; verify
A7: 006 | B7: Midjourney | C7: Image | D7: =Calendar!F7 -> E006 | E7: =Calendar!B7 -> 46316 | F7: No free tier (Field sketch) | G7: Check for program | H7: Free-tier note from 2026 comparison articles; verify
A8: 007 | B8: ElevenLabs | C8: Audio | D8: =Calendar!F8 -> E007 | E8: =Calendar!B8 -> 46317 | F8: Free: monthly characters, attribution required | G8: Confirmed program | H8: https://zplatform.ai/best-ai-tools/best-ai-affiliate-programs/
A9: 008 | B9: Photoroom | C9: Image | D9: =Calendar!F9 -> E008 | E9: =Calendar!B9 -> 46317 | F9: Free tier | G9: Check for program | H9: Free-tier note from 2026 comparison articles; verify
A10: 009 | B10: Hitem3D | C10: 3D | D10: =Calendar!F11 -> E010 | E10: =Calendar!B11 -> 46318 | F10: Free tier (verify) | G10: Check for program | H10: Verify on the tool's pricing page
A11: 010 | B11: Gamma | C11: Work | D11: =Calendar!F12 -> E011 | E11: =Calendar!B12 -> 46319 | F11: Free credits | G11: Check for program | H11: Free-tier note from 2026 comparison articles; verify
A12: 011 | B12: Gemini image | C12: Image | D12: =Calendar!F13 -> E012 | E12: =Calendar!B13 -> 46319 | F12: Free in Gemini app | G12: No program known (Unpaid) | H12: Free-tier note from 2026 comparison articles; verify
A13: 012 | B13: NotebookLM | C13: Work | D13: =Calendar!F17 -> E016 | E13: =Calendar!B17 -> 46321 | F13: Free | G13: No program known (Unpaid) | H13: Free-tier note from 2026 comparison articles; verify
A14: 013 | B14: Happy Shrimp | C14: Audio | D14: =Calendar!F18 -> E017 | E14: =Calendar!B18 -> 46322 | F14: Free (verify) | G14: No program known (Unpaid) | H14: Verify on the tool's pricing page
A15: 014 | B15: Lovable | C15: Build | D15: =Calendar!F19 -> E018 | E15: =Calendar!B19 -> 46322 | F15: Free daily credits | G15: Check for program | H15: Free-tier note from 2026 comparison articles; verify
A16: 015 | B16: Hailuo (MiniMax) | C16: Video | D16: =Calendar!F20 -> E019 | E16: =Calendar!B20 -> 46323 | F16: Free daily clips | G16: Check for program | H16: Free-tier note from 2026 comparison articles; verify
A17: 016 | B17: Seedance (Dreamina) | C17: Video | D17: =Calendar!F20 -> E019 | E17: =Calendar!B20 -> 46323 | F17: Free daily credits, 1080p no watermark (verify) | G17: Check for program | H17: Verify on the tool's pricing page
A18: 017 | B18: Veo 3.1 (Flow) | C18: Video | D18: =Calendar!F21 -> E020 | E18: =Calendar!B21 -> 46323 | F18: Paid Google AI plan (Field sketch) | G18: No program known (Unpaid) | H18: Free-tier note from 2026 comparison articles; verify
A19: 018 | B19: Hookest | C19: Creator | D19: =Calendar!F25 -> E024 | E19: =Calendar!B25 -> 46325 | F19: Free tier (verify) | G19: Check for program | H19: Verify on the tool's pricing page
A20: 019 | B20: Ideogram | C20: Image | D20: =Calendar!F26 -> E025 | E20: =Calendar!B26 -> 46326 | F20: Free daily credits | G20: Check for program | H20: Free-tier note from 2026 comparison articles; verify
A21: 020 | B21: Adobe Podcast Enhance | C21: Audio | D21: =Calendar!F27 -> E026 | E21: =Calendar!B27 -> 46326 | F21: Free tier | G21: No program known (Unpaid) | H21: Free-tier note from 2026 comparison articles; verify
A22: 021 | B22: Chit | C22: Work | D22: =Calendar!F29 -> E028 | E22: =Calendar!B29 -> 46327 | F22: Free (verify) | G22: No program known (Unpaid) | H22: Verify on the tool's pricing page
A23: 022 | B23: HeyGen | C23: Avatar | D23: =Calendar!F30 -> E029 | E23: =Calendar!B30 -> 46328 | F23: Free plan, short videos | G23: Confirmed program | H23: https://zplatform.ai/best-ai-tools/best-ai-affiliate-programs/
A24: 023 | B24: Goblin Tools | C24: Work | D24: =Calendar!F31 -> E030 | E24: =Calendar!B31 -> 46328 | F24: Free | G24: No program known (Unpaid) | H24: Free-tier note from 2026 comparison articles; verify
A25: 024 | B25: Lovart | C25: Image | D25: =Calendar!F32 -> E031 | E25: =Calendar!B32 -> 46329 | F25: Free credits (verify) | G25: Check for program | H25: Verify on the tool's pricing page
A26: 025 | B26: Descript | C26: Creator | D26: =Calendar!F33 -> E032 | E26: =Calendar!B33 -> 46329 | F26: Free plan | G26: Confirmed program | H26: https://zplatform.ai/best-ai-tools/best-ai-affiliate-programs/
A27: 026 | B27: Recraft | C27: Image | D27: =Calendar!F34 -> E033 | E27: =Calendar!B34 -> 46330 | F27: Free tier | G27: Check for program | H27: Free-tier note from 2026 comparison articles; verify
A28: 027 | B28: Synthesia | C28: Avatar | D28: =Calendar!F35 -> E034 | E28: =Calendar!B35 -> 46330 | F28: Free plan limited (Field sketch) | G28: Confirmed program | H28: https://affiliatejob.org/blog/highest-paying-ai-tool-affiliate-programs-2026
A29: 028 | B29: Vizcom | C29: Image | D29: =Calendar!F39 -> E038 | E29: =Calendar!B39 -> 46332 | F29: Free plan (verify) | G29: Check for program | H29: Verify on the tool's pricing page
A30: 029 | B30: Google Stitch | C30: Build | D30: =Calendar!F41 -> E040 | E30: =Calendar!B41 -> 46333 | F30: Free (Google Labs) | G30: No program known (Unpaid) | H30: Free-tier note from 2026 comparison articles; verify
A31: 030 | B31: Suno | C31: Audio | D31: =Calendar!F44 -> E043 | E31: =Calendar!B44 -> 46335 | F31: Free daily credits, non-commercial | G31: Check for program | H31: Free-tier note from 2026 comparison articles; verify
A32: 031 | B32: Napkin | C32: Image | D32: =Calendar!F45 -> E044 | E32: =Calendar!B45 -> 46335 | F32: Free plan | G32: Check for program | H32: Free-tier note from 2026 comparison articles; verify
A33: 032 | B33: Tucky | C33: Work | D33: =Calendar!F46 -> E045 | E33: =Calendar!B46 -> 46336 | F33: Free (verify) | G33: No program known (Unpaid) | H33: Verify on the tool's pricing page
A34: 033 | B34: Wispr Flow | C34: Work | D34: =Calendar!F47 -> E046 | E34: =Calendar!B47 -> 46336 | F34: Free tier | G34: Check for program | H34: Free-tier note from 2026 comparison articles; verify
A35: 034 | B35: Clipdrop | C35: Image | D35: =Calendar!F48 -> E047 | E35: =Calendar!B48 -> 46337 | F35: Free tools with limits | G35: Check for program | H35: Free-tier note from 2026 comparison articles; verify
A36: 035 | B36: Canva AI | C36: Image | D36: =Calendar!F48 -> E047 | E36: =Calendar!B48 -> 46337 | F36: Free plan with AI limits | G36: Check for program | H36: Free-tier note from 2026 comparison articles; verify
A37: 036 | B37: Magnific | C37: Image | D37: =Calendar!F49 -> E048 | E37: =Calendar!B49 -> 46337 | F37: Paid (Field sketch) | G37: Check for program | H37: Free-tier note from 2026 comparison articles; verify
A38: 037 | B38: OpusClip | C38: Creator | D38: =Calendar!F50 -> E049 | E38: =Calendar!B50 -> 46338 | F38: Free monthly minutes | G38: Check for program | H38: Free-tier note from 2026 comparison articles; verify
A39: 038 | B39: Socrates AI | C39: Work | D39: =Calendar!F53 -> E052 | E39: =Calendar!B53 -> 46339 | F39: Free (verify) | G39: No program known (Unpaid) | H39: Verify on the tool's pricing page
A40: 039 | B40: Krea | C40: Image | D40: =Calendar!F54 -> E053 | E40: =Calendar!B54 -> 46340 | F40: Free tier | G40: Check for program | H40: Free-tier note from 2026 comparison articles; verify
...

Sheet Series
A1: Series | B1: Code | C1: Purpose | D1: Mode | E1: Signature opening | F1: Episodes in 90 days
A2: Field Specimen | B2: FS | C2: Flagship. One tool, one real test, conditions card, flaw, verdict. | D2: Live specimen | E2: Cold open on output; full anatomy | F2: =COUNTIF(Calendar!$H$2:$H$181,A2) -> 52
A3: Free Range | B3: FR | C3: What the free tier actually gets you, in numbers. No card needed. | D3: Live specimen | E3: Opens on a counter: credits used / credits left | F3: =COUNTIF(Calendar!$H$2:$H$181,A3) -> 26
A4: Rare Sighting | B4: RS | C4: A tool most people haven't heard of yet. Speed beats polish. | D4: Live or Field sketch | E4: Opens on the RARE SIGHTING stamp and launch date | F4: =COUNTIF(Calendar!$H$2:$H$181,A4) -> 32
A5: Plate | B5: PL | C5: Same input, three tools, side-by-side triptych. Highest search intent. | D5: Live specimen | E5: Three columns, one shared input card, ranked at the end | F5: =COUNTIF(Calendar!$H$2:$H$181,A5) -> 13
A6: Field Sketch | B6: SK | C6: Desk study of a paid tool. Labelled 'not hands-on'. Verdict is 'Watch'. | D6: Field sketch | E6: Pencil-line diagrams redrawn from public info; price math | F6: =COUNTIF(Calendar!$H$2:$H$181,A6) -> 13
A7: Mimicry | B7: MI | C7: AI or real? Viewers comment A or B; reveal at the end. | D7: Live specimen | E7: Split screen A/B; answer revealed after a 3 s countdown | F7: =COUNTIF(Calendar!$H$2:$H$181,A7) -> 13
A8: Dissection | B8: DS | C8: A workflow chaining 2-3 tools to make one finished thing. | D8: Live specimen | E8: Numbered stages laid out like a dissection tray | F8: =COUNTIF(Calendar!$H$2:$H$181,A8) -> 13
A9: The Drawer | B9: DR | C9: Sunday recap: every specimen pinned this week, in 30 s. | D9: Built from the week's renders | E9: Drawer opens; each label lights up with its verdict | F9: =COUNTIF(Calendar!$H$2:$H$181,A9) -> 12
A10: Extinction Watch | B10: EX | C10: A tool or model that died or changed, and what replaced it. | D10: Field sketch | E10: Ink-black label; crossed-out specimen; successors pinned | F10: =COUNTIF(Calendar!$H$2:$H$181,A10) -> 6
A11: Total | F11: =SUM(F2:F10) -> 180

Sheet Scorecard
A1: Week | B1: Week starts | C1: Views (all platforms) | D1: Engaged views (YT) | E1: Avg % viewed (YT) | F1: Comments with a code (IG) | G1: Hub visits | H1: Affiliate clicks | I1: Sign-ups | J1: Paid conversions | K1: Commission earned ($) | L1: Hub visits per 1k views | M1: Click-through from hub | N1: Sign-up rate | O1: Paid rate | P1: Top episode | Q1: Decision for next week
A2: 1 | B2: =Settings!$B$3+(A2-1)*7 -> 46314 | L2: =IF(C2>0,G2/C2*1000,0) -> 0 | M2: =IF(G2>0,H2/G2,0) -> 0 | N2: =IF(H2>0,I2/H2,0) -> 0 | O2: =IF(I2>0,J2/I2,0) -> 0
A3: 2 | B3: =Settings!$B$3+(A3-1)*7 -> 46321 | L3: =IF(C3>0,G3/C3*1000,0) -> 0 | M3: =IF(G3>0,H3/G3,0) -> 0 | N3: =IF(H3>0,I3/H3,0) -> 0 | O3: =IF(I3>0,J3/I3,0) -> 0
A4: 3 | B4: =Settings!$B$3+(A4-1)*7 -> 46328 | L4: =IF(C4>0,G4/C4*1000,0) -> 0 | M4: =IF(G4>0,H4/G4,0) -> 0 | N4: =IF(H4>0,I4/H4,0) -> 0 | O4: =IF(I4>0,J4/I4,0) -> 0
A5: 4 | B5: =Settings!$B$3+(A5-1)*7 -> 46335 | L5: =IF(C5>0,G5/C5*1000,0) -> 0 | M5: =IF(G5>0,H5/G5,0) -> 0 | N5: =IF(H5>0,I5/H5,0) -> 0 | O5: =IF(I5>0,J5/I5,0) -> 0
A6: 5 | B6: =Settings!$B$3+(A6-1)*7 -> 46342 | L6: =IF(C6>0,G6/C6*1000,0) -> 0 | M6: =IF(G6>0,H6/G6,0) -> 0 | N6: =IF(H6>0,I6/H6,0) -> 0 | O6: =IF(I6>0,J6/I6,0) -> 0
A7: 6 | B7: =Settings!$B$3+(A7-1)*7 -> 46349 | L7: =IF(C7>0,G7/C7*1000,0) -> 0 | M7: =IF(G7>0,H7/G7,0) -> 0 | N7: =IF(H7>0,I7/H7,0) -> 0 | O7: =IF(I7>0,J7/I7,0) -> 0
A8: 7 | B8: =Settings!$B$3+(A8-1)*7 -> 46356 | L8: =IF(C8>0,G8/C8*1000,0) -> 0 | M8: =IF(G8>0,H8/G8,0) -> 0 | N8: =IF(H8>0,I8/H8,0) -> 0 | O8: =IF(I8>0,J8/I8,0) -> 0
A9: 8 | B9: =Settings!$B$3+(A9-1)*7 -> 46363 | L9: =IF(C9>0,G9/C9*1000,0) -> 0 | M9: =IF(G9>0,H9/G9,0) -> 0 | N9: =IF(H9>0,I9/H9,0) -> 0 | O9: =IF(I9>0,J9/I9,0) -> 0
A10: 9 | B10: =Settings!$B$3+(A10-1)*7 -> 46370 | L10: =IF(C10>0,G10/C10*1000,0) -> 0 | M10: =IF(G10>0,H10/G10,0) -> 0 | N10: =IF(H10>0,I10/H10,0) -> 0 | O10: =IF(I10>0,J10/I10,0) -> 0
A11: 10 | B11: =Settings!$B$3+(A11-1)*7 -> 46377 | L11: =IF(C11>0,G11/C11*1000,0) -> 0 | M11: =IF(G11>0,H11/G11,0) -> 0 | N11: =IF(H11>0,I11/H11,0) -> 0 | O11: =IF(I11>0,J11/I11,0) -> 0
A12: 11 | B12: =Settings!$B$3+(A12-1)*7 -> 46384 | L12: =IF(C12>0,G12/C12*1000,0) -> 0 | M12: =IF(G12>0,H12/G12,0) -> 0 | N12: =IF(H12>0,I12/H12,0) -> 0 | O12: =IF(I12>0,J12/I12,0) -> 0
A13: 12 | B13: =Settings!$B$3+(A13-1)*7 -> 46391 | L13: =IF(C13>0,G13/C13*1000,0) -> 0 | M13: =IF(G13>0,H13/G13,0) -> 0 | N13: =IF(H13>0,I13/H13,0) -> 0 | O13: =IF(I13>0,J13/I13,0) -> 0
A14: 13 | B14: =Settings!$B$3+(A14-1)*7 -> 46398 | L14: =IF(C14>0,G14/C14*1000,0) -> 0 | M14: =IF(G14>0,H14/G14,0) -> 0 | N14: =IF(H14>0,I14/H14,0) -> 0 | O14: =IF(I14>0,J14/I14,0) -> 0
A15: Total | C15: =SUM(C2:C14) -> 0 | D15: =SUM(D2:D14) -> 0 | F15: =SUM(F2:F14) -> 0 | G15: =SUM(G2:G14) -> 0 | H15: =SUM(H2:H14) -> 0 | I15: =SUM(I2:I14) -> 0 | J15: =SUM(J2:J14) -> 0 | K15: =SUM(K2:K14) -> 0
A16: Fill one row every Sunday from YouTube Studio, Instagram Insights, X Analytics and each affiliate dashboard. Targets for weeks 1-4: avg % viewed > 80%, hub visits > 2 per 1k views.
